I'm sorry, but an uncaught exception occurred.

While running game code:
  File "game/options.rpy", line 50, in script
    define config.has_voice = fa
  File "game/options.rpy", line 50, in <module>
    define config.has_voice = fa
NameError: name 'fa' is not defined

-- Full Traceback ------------------------------------------------------------

Full traceback:
  File "game/options.rpy", line 50, in script
    define config.has_voice = fa
  File "C:\Users\Shadow\Downloads\renpy-8.2.1-sdk\renpy\ast.py", line 2219, in execute
    self.set()
  File "C:\Users\Shadow\Downloads\renpy-8.2.1-sdk\renpy\ast.py", line 2233, in set
    value = renpy.python.py_eval_bytecode(self.code.bytecode)
  File "C:\Users\Shadow\Downloads\renpy-8.2.1-sdk\renpy\python.py", line 1202, in py_eval_bytecode
    return eval(bytecode, globals, locals)
  File "game/options.rpy", line 50, in <module>
    define config.has_voice = fa
NameError: name 'fa' is not defined

Windows-10-10.0.22621 AMD64
Ren'Py 8.2.1.24030407
The Rise of Price 0.3
Wed Mar 20 22:33:56 2024
